Workbook

Sheet 化学品用量
B1: 除油粉
A2: 槽名 | B2: 槽积(L) | C2: 月使用量（KG） | D2: 42826 | E2: 42827 | F2: 42828 | G2: 42829 | H2: 42830 | I2: 42831 | J2: 42832 | K2: 42833 | L2: 42834 | M2: 42835 | N2: 42836 | O2: 42837 | P2: 42838 | Q2: 42839 | R2: 42840 | S2: 42841 | T2: 42842 | U2: 42843 | V2: 42844 | W2: 42845 | X2: 42846 | Y2: 42847 | Z2: 42848 | AA2: 42849 | AB2: 42850 | AC2: 42851 | AD2: 42852 | AE2: 42853 | AF2: 42854 | AG2: 42855
C3: =SUM(D3:AH3) -> 0 | D3: =分析记录4.1!$H6 -> 0
C4: =SUM(D4:AH4) -> #REF! | D4: =分析记录4.1!#REF! -> #REF!
C5: =SUM(D5:AH5) -> #REF! | D5: =分析记录4.1!#REF! -> #REF!
C6: =SUM(D6:AH6) -> #REF! | D6: =分析记录4.1!#REF! -> #REF!
C7: =SUM(D7:AH7) -> 0 | D7: =分析记录4.1!$H8 -> 0
C8: =SUM(D8:AH8) -> 0 | D8: =分析记录4.1!$H9 -> 0
C9: =SUM(D9:AH9) -> 0 | D9: =分析记录4.1!$H10 -> 0
C10: =SUM(D10:AH10) -> 0 | D10: =分析记录4.1!$H11 -> 0
C11: =SUM(D11:AH11) -> 0 | D11: =分析记录4.1!$H12 -> 0
C12: =SUM(D12:AH12) -> 0 | D12: =分析记录4.1!$H13 -> 0
C13: =SUM(D13:AH13) -> 0 | D13: =分析记录4.1!$H14 -> 0
C14: =SUM(D14:AH14) -> 0 | D14: =分析记录4.1!$H15 -> 0
C15: =SUM(D15:AH15) -> 0 | D15: =分析记录4.1!$H24 -> 0
C16: =SUM(D16:AH16) -> #REF! | D16: =分析记录4.1!#REF! -> #REF!
C17: =SUM(D17:AH17) -> #REF! | D17: =分析记录4.1!#REF! -> #REF!
C18: =SUM(D18:AH18) -> 0 | D18: =分析记录4.1!$H29 -> 0 | AY18: =#REF! -> #REF!
C19: =SUM(D19:AH19) -> 0 | D19: =分析记录4.1!$H30 -> 0
C20: =SUM(D20:AH20) -> 0 | D20: =分析记录4.1!$H31 -> 0
C21: =SUM(D21:AH21) -> #REF! | D21: =分析记录4.1!#REF! -> #REF!
C22: =SUM(D22:AH22) -> #REF! | D22: =分析记录4.1!#REF! -> #REF!
C23: =SUM(D23:AH23) -> #REF! | D23: =分析记录4.1!#REF! -> #REF!
C24: =SUM(D24:AH24) -> #REF! | D24: =分析记录4.1!#REF! -> #REF!
C25: =SUM(D25:AH25) -> #REF! | D25: =分析记录4.1!#REF! -> #REF!
C26: =SUM(D26:AH26) -> #REF! | D26: =分析记录4.1!#REF! -> #REF!
C27: =SUM(D27:AH27) -> #REF! | D27: =分析记录4.1!#REF! -> #REF!
A28: =C29-C28 -> #REF! | B28: 出库 | C28: =SUM(C3:C27) -> #REF! | D28: =SUM(D3:D27) -> #REF! | E28: =SUM(E3:E27) -> 0 | F28: =SUM(F3:F27) -> 0 | G28: =SUM(G3:G27) -> 0 | H28: =SUM(H3:H27) -> 0 | I28: =SUM(I3:I27) -> 0 | J28: =SUM(J3:J27) -> 0 | ... AH28: =SUM(AH3:AH27) -> 0
B29: 入库 | C29: =SUM($D$29:$AH$29) -> 0
B33: 活化药水
A34: 槽名 | B34: 槽积(L) | C34: 月使用量（KG） | D34: 42826 | E34: 42827 | F34: 42828 | G34: 42829 | H34: 42830 | I34: 42831 | J34: 42832 | K34: 42833 | L34: 42834 | M34: 42835 | N34: 42836 | O34: 42837 | P34: 42838 | Q34: 42839 | R34: 42840 | S34: 42841 | T34: 42842 | U34: 42843 | V34: 42844 | W34: 42845 | X34: 42846 | Y34: 42847 | Z34: 42848 | AA34: 42849 | AB34: 42850 | AC34: 42851 | AD34: 42852 | AE34: 42853 | AF34: 42854 | AG34: 42855
C35: =SUM(D35:AH35) -> #REF! | D35: =分析记录4.1!#REF! -> #REF! | E35: =分析记录4.1!#REF! -> #REF! | F35: =分析记录4.1!#REF! -> #REF! | G35: =分析记录4.1!#REF! -> #REF! | H35: 0 | I35: =分析记录4.1!#REF! -> #REF! | J35: =分析记录4.1!#REF! -> #REF! | K35: 0 | L35: 0 | M35: =分析记录4.1!#REF! -> #REF! | N35: =分析记录4.1!#REF! -> #REF! | O35: 0 | P35: =分析记录4.1!#REF! -> #REF! | Q35: =分析记录4.1!#REF! -> #REF! | R35: =分析记录4.1!#REF! -> #REF! | S35: =分析记录4.1!#REF! -> #REF! | T35: =分析记录4.1!#REF! -> #REF! | U35: =分析记录4.1!#REF! -> #REF! | V35: 0 | W35: =分析记录4.1!#REF! -> #REF! | X35: =分析记录4.1!#REF! -> #REF! | Y35: 0 | Z35: =分析记录4.1!#REF! -> #REF! | AA35: =分析记录4.1!#REF! -> #REF! | AB35: =分析记录4.1!#REF! -> #REF! | AC35: 0 | AD35: =分析记录4.1!#REF! -> #REF! | AE35: =分析记录4.1!#REF! -> #REF! | AF35: 0 | AG35: =分析记录4.1!#REF! -> #REF! | AH35: =分析记录4.1!#REF! -> #REF!
C36: =SUM(D36:AH36) -> #REF! | D36: =分析记录4.1!#REF! -> #REF! | H36: 0 | K36: 0 | L36: 0 | O36: 0 | V36: 0 | Y36: 0 | AC36: 0 | AF36: 0
C37: =SUM(D37:AH37) -> #REF! | D37: =分析记录4.1!#REF! -> #REF! | H37: 0 | K37: 0 | L37: 0 | O37: 0 | V37: 0 | Y37: 0 | AC37: 0 | AF37: 0
C38: =SUM(D38:AH38) -> #REF! | D38: =分析记录4.1!#REF! -> #REF! | H38: 0 | K38: 0 | L38: 0 | O38: 0 | V38: 0 | Y38: 0 | AC38: 0 | AF38: 0
C39: =SUM(D39:AH39) -> #REF! | D39: =分析记录4.1!#REF! -> #REF! | H39: 0 | K39: 0 | L39: 0 | O39: 0 | V39: 0 | Y39: 0 | AC39: 0 | AF39: 0
C40: =SUM(D40:AH40) -> #REF! | D40: =分析记录4.1!#REF! -> #REF! | H40: 0 | K40: 0 | L40: 0 | O40: 0 | V40: 0 | Y40: 0 | AC40: 0 | AF40: 0
C41: =SUM(D41:AH41) -> #REF! | D41: =分析记录4.1!#REF! -> #REF! | H41: 0 | K41: 0 | L41: 0 | O41: 0 | V41: 0 | Y41: 0 | AC41: 0 | AF41: 0
C42: =SUM(D42:AH42) -> #REF! | D42: =分析记录4.1!#REF! -> #REF! | H42: 0 | K42: 0 | L42: 0 | O42: 0 | V42: 0 | Y42: 0 | AC42: 0 | AF42: 0
C43: =SUM(D43:AH43) -> #REF! | D43: =分析记录4.1!#REF! -> #REF! | H43: 0 | K43: 0 | L43: 0 | O43: 0 | V43: 0 | Y43: 0 | AC43: 0 | AF43: 0
...

Sheet 分析记录4.1
A1: 万明电镀智能科技（东莞）有限公司 前处理分析报表 日期：
D3: 早 | F3: 晚
B4: 机台 | C4: 槽名 | D4: 分析值 (Be°) | E4: 补加量 (kg) | F4: 分析值 (Be°) | G4: 补加量 (kg) | H4: 备注
A5: 超声除油 电解除油 | B5: R | C5: R超声波脱脂
C6: R电解脱脂1
C7: R电解脱脂2
B8: S | C8: S超声波脱脂
C9: S电解脱脂1
C10: S电解脱脂2
C11: S电解脱脂3
B12: T | C12: T超声波脱脂
C13: T电解脱脂1
C14: T电解脱脂2
C15: T电解脱脂3
B16: U1U2 | C16: U超声波脱脂
C17: U电解脱脂1
C18: U电解脱脂2
C19: U电解脱脂3
B20: U3U4 | C20: U超声波脱脂
C21: U电解脱脂1
C22: U电解脱脂2
C23: U电解脱脂3
A24: 抛光 | B24: R2 | C24: 3212抛光
B25: S1S2 | C25: 微蚀
B26: T1T2 | C26: 微蚀
B27: U1U2 | C27: 微蚀
B28: U3U4 | C28: 微蚀
A29: 活化 | B29: R | C29: 活化
B30: S | C30: 活化
B31: T | C31: 活化
B32: U1U2 | C32: 活化
B33: U3U4 | C33: 活化
A34: 锡保护 | B34: S | C34: 锡保护
A35: 水封 | B35: S-1 | C35: 金封孔剂
B36: S-2 | C36: 金封孔剂
B37: T1T2 | C37: 金封孔剂
B38: U1U2 | C38: 封孔剂
B39: U3 | C39: 金封孔剂
A40: 核准： | D40: 审核： | G40: 作成：
F42: 表单编号：WM-QR-GC-004/A
...

Sheet 分析记录4.1 (2)
A1: 万明电镀智能科技（东莞）有限公司 镍槽分析报表 日期：
C3: 早 | F3: 晚
A4: 机台 | B4: 槽名 | C4: 分析值 (Be°/PH) | E4: 补加量 (kg) | F4: 分析值 (Be°/PH) | H4: 补加量 (kg) | I4: 备注
A5: R | B5: R1普镍
B6: R1高温镍
B7: R2预镀镍
B8: R2普镍
B9: R2高温镍
B10: R2预镀钯
A11: S | B11: S1预镀镍
B12: S1普镍
B13: S高温镍
B14: S预镀钯
B15: S2修正镍
B16: S2普镍
A17: T | B17: T1预镀镍
B18: T1普镍
B19: T1高温镍
B20: T预镀钯
B21: T2普镍
B22: T2镍钨
B23: T2高温镍
A24: U | B24: U1预镀镍
B25: U1修正镍
B26: U1雾镍
B27: U1普镍
B28: U1高温镍
B29: U2预镀镍
B30: U2修正镍
B31: U2雾镍
B32: U2普镍
B33: U2高温镍
A34: 核准： | C34: 审核： | F34: 作成：
F36: 表单编号：WM-QR-GC-004/A
A37: 注意：以上各浓度管控随端子结构不同会有实时变化，所有参数必须在规定控制范围不可出现超差；
